Workbook

Sheet Hoja 1
A1: FECHA | B1: MES | C1: SEMANA | D1: Nombre | E1: Apellido | F1: WhatsApp | G1: #Orden | H1: Pregunta 1 | I1: Pregunta 2 | J1: Click Google | K1: Premio Entregado por Asesor | L1: TALLER | M1: Fecha Premio Entregado | N1: Taller | O1: Referencia
A2: 46057 | B2: =+MONTH(A2) -> 2 | C2: =+WEEKNUM(A2) -> 6 | D2: SEBASTIAN | E2: BULLA | F2: 573002308392 | G2: 78670 | H2: Bueno | I2: Buena | J2: Buena movilidad y buen servicio. | K2: Inicio | M2: Taller av chile
A3: 46057 | B3: =+MONTH(A3) -> 2 | C3: =+WEEKNUM(A3) -> 6 | D3: RAFAEL ARAMIS | E3: PINZON RAMOS | F3: 573105583071 | G3: 78424 | H3: Bueno | I3: Buena | J3: Tener mas accesorios utiles para la patineta, mas personalizaciones, tener en cuentanla calidad de los accesorios ya que parece qje no fueran de buena calidad | K3: Inicio | M3: Minca Calle 72 con 24
A4: 46057 | B4: =+MONTH(A4) -> 2 | C4: =+WEEKNUM(A4) -> 6 | D4: JOSE | E4: LOPEZ TORRES | F4: 573213733338 | G4: 78667 | H4: Regular | I4: Buena | J4: La marca buena y la primer ida al taller pues no fue del todo satisfactoria. | M4: Chico
A5: 46057 | B5: =+MONTH(A5) -> 2 | C5: =+WEEKNUM(A5) -> 6 | D5: JUAN CARLOS | E5: GÓMEZ | F5: 573214518618 | G5: 78099 | H5: Bueno | I5: Buena | J5: Sin comentarios | K5: Inicio | M5: Calle 72
A6: 46057 | B6: =+MONTH(A6) -> 2 | C6: =+WEEKNUM(A6) -> 6 | D6: CRISTHIAN HERNANDO | E6: BOTERO YAIMA | F6: 573244760565 | G6: 78001 | H6: Bueno | I6: Buena | J6: Fue todo exelente desde la atención hasta como quedó la moto | K6: Inicio | M6: En el de Av chile
A7: 46057 | B7: =+MONTH(A7) -> 2 | C7: =+WEEKNUM(A7) -> 6 | D7: JULIAN | E7: CADAVID | F7: 573016559943 | G7: 78565 | H7: Bueno | I7: Buena | J7: Todo muy bien | K7: Inicio | M7: Cedritos
A8: 46057 | B8: =+MONTH(A8) -> 2 | C8: =+WEEKNUM(A8) -> 6 | D8: JUAN NICOLAS | E8: REYES RESTREPO | F8: 573214588554 | G8: 78246 | H8: Bueno | I8: Buena | J8: Lo único es que ayer se me hizo una cotización, y cuando pagué se había aumentado un adicional que subió mucho el costo y no me llegó una notificación de este cambio, no hubo problema pero creo que es algo de tener cuidado | K8: Inicio | M8: Chico
A9: 46057 | B9: =+MONTH(A9) -> 2 | C9: =+WEEKNUM(A9) -> 6 | D9: NORIS ISABEL | E9: ARIAS TAPIA | F9: 573135900380 | G9: 78298 | H9: Bueno | I9: Buena | J9: Es una excelente marca | K9: Inicio | M9: .
A10: 46057 | B10: =+MONTH(A10) -> 2 | C10: =+WEEKNUM(A10) -> 6 | D10: LINDA CAROLINA | E10: RUIZ MORALES | F10: 573232742435 | G10: 77636 | H10: Bueno | I10: Buena | J10: Me encantaría que sacaran baúles mas grandes para la moped | K10: Inicio | M10: Av Chile
A11: 46057 | B11: =+MONTH(A11) -> 2 | C11: =+WEEKNUM(A11) -> 6 | D11: LUCAS | E11: MESA MEJIA | F11: 573102619373 | G11: 77899 | H11: Bueno | I11: Buena | J11: Gracias | K11: Inicio | M11: .
A12: 46057 | B12: =+MONTH(A12) -> 2 | C12: =+WEEKNUM(A12) -> 6 | D12: NICOLAS ALEXANDER | E12: PINZON QUINTERO | F12: 573194141745 | G12: 78187 | H12: Bueno | I12: Buena | J12: Estuvo mejor la atención que las anteriores veces, me quedo un ruido en la patineta que iré el sábado a que me revisen | K12: Inicio | M12: Cedritos
A13: 46057 | B13: =+MONTH(A13) -> 2 | C13: =+WEEKNUM(A13) -> 6 | D13: BRIAN NORBERTO | E13: DIAZ OSPITIA | F13: 573023363600 | G13: 78093 | H13: Bueno | I13: Buena | J13: Excelente atención y trabajo mi Minca quedó perfecta muchas gracias! | K13: Inicio | M13: Cedritos
A14: 46057 | B14: =+MONTH(A14) -> 2 | C14: =+WEEKNUM(A14) -> 6 | D14: HAROLD ORLANDO | E14: GUZMAN UCEDA | F14: 573170111185 | G14: 78607 | H14: Bueno | I14: Buena | J14: Fui primero al taller de av chile, pero me atendieron super feo, por eso fui a chicó. | K14: Inicio | M14: Chico
A15: 46057 | B15: =+MONTH(A15) -> 2 | C15: =+WEEKNUM(A15) -> 6 | D15: CATERIN | E15: FRANCO FERNANDEZ | F15: 573058397345 | G15: 78564 | H15: Bueno | I15: Buena | J15: Muy buena | K15: Inicio | M15: Av 19
A16: 46057 | B16: =+MONTH(A16) -> 2 | C16: =+WEEKNUM(A16) -> 6 | D16: RAUL | E16: HIDALGO RODRIGUEZ | F16: 573134427727 | G16: 77865 | H16: Bueno | I16: Buena | J16: En general l la atención fue buena aunque . Sería bueno que tuvieran mejor stock de repuestos . Yo tuve que sacar la patineta sin pantalla porque la necesito usar. | K16: Inicio | M16: Créditos
A17: 46057 | B17: =+MONTH(A17) -> 2 | C17: =+WEEKNUM(A17) -> 6 | D17: SANTIAGO | E17: VALENCIA | F17: 573107852688 | G17: 76114 | H17: Bueno | I17: Buena | K17: Inicio | M17: 95
A18: 46057 | B18: =+MONTH(A18) -> 2 | C18: =+WEEKNUM(A18) -> 6 | D18: SAMUEL ANDRES | E18: ORTIZ ROMERO | F18: 573188665160 | G18: 78222 | H18: Bueno | I18: Buena | J18: Tuvo un pequeño detalle al momento de la entrega, fue solucionado de inmediato, entonces, 10 puntos | K18: Inicio | M18: Chicó
A19: 46057 | B19: =+MONTH(A19) -> 2 | C19: =+WEEKNUM(A19) -> 6 | D19: MONICA ALEJANDRA | E19: ORJUELA PRIETO | F19: 573203316724 | G19: 78038 | H19: Bueno | I19: Regular | J19: El mantenimiento fue bueno, solo que se demoraron bastante el el proceso, ya que segun los tiempo que me habían dado el dia lunes debían entregarme y hasta el día lunes empezó la revisión, significa que la patineta estuvo quita sin revisión desde el miércoles que la lleve | M19: Av chile
A20: 46057 | B20: =+MONTH(A20) -> 2 | C20: =+WEEKNUM(A20) -> 6 | D20: CARLOS ANDRES | E20: TAVERA ALPIZAR | F20: 573209927868 | G20: 78196 | H20: Bueno | I20: Buena | J20: El servicio es muy bueno y quede muy satisfecho con la revisión de mi patineta | K20: Inicio | M20: 140 con 19
A21: 46056 | B21: =+MONTH(A21) -> 2 | C21: =+WEEKNUM(A21) -> 6 | D21: OSCAR DANIEL | E21: HERRERA ZÁRATE | F21: 573186279231 | G21: 77930 | H21: Regular | I21: Buena | J21: Primero el 26 de enero me informaron que en 2 días estaría lista. Después que el 31, y tampoco estuvo lista y finalmente me la entregaron el 3 de febrero. Ni un mantenimiento general tarda tanto. Solamente era un cambio de piñón trasero | M21: Av Chile
A22: 46056 | B22: =+MONTH(A22) -> 2 | C22: =+WEEKNUM(A22) -> 6 | D22: ALEXANDER | E22: ROZO | F22: 573202630410 | G22: 77660 | H22: Bueno | I22: Buena | J22: un gran servicio con calidad y amabilidad | K22: Inicio | M22: Javeriana
A23: 46056 | B23: =+MONTH(A23) -> 2 | C23: =+WEEKNUM(A23) -> 6 | D23: DAVID ESTEBAN | E23: LOTERO GONZALEZ | F23: 573195505581 | G23: 78473 | H23: Bueno | I23: Buena | K23: Inicio | M23: Chico
A24: 46056 | B24: =+MONTH(A24) -> 2 | C24: =+WEEKNUM(A24) -> 6 | D24: JONATHAN DAVID | E24: TORRES | F24: 573002182101 | G24: 78209 | H24: Bueno | I24: Buena | J24: Excelente la mejor inversión | K24: Inicio | M24: Av chile
A25: 46056 | B25: =+MONTH(A25) -> 2 | C25: =+WEEKNUM(A25) -> 6 | D25: MATEO | E25: MORALES CORREA | F25: 573228136150 | G25: 78539 | H25: Bueno | I25: Buena | J25: Excelente marca buena calidad de esos productos | K25: Inicio | M25: Chico
A26: 46056 | B26: =+MONTH(A26) -> 2 | C26: =+WEEKNUM(A26) -> 6 | D26: DIANA MARCELA | E26: DIAZ CARO | F26: 573214560160 | G26: 78329 | H26: Bueno | I26: Buena | J26: Muchas gracias porque tomaron atenta nota de todos los detalles que tenía mi patineta y quedó como nueva 😄 | K26: Inicio | M26: Calle 72
A27: 46056 | B27: =+MONTH(A27) -> 2 | C27: =+WEEKNUM(A27) -> 6 | D27: GIOVANNY ALBERTO | E27: MONTOYA PINZON | F27: 573151422990 | G27: 78509 | H27: Bueno | I27: Buena | J27: Me encanta las herramientas tecnológicas que usan para agendar citas, hacer seguimiento y entrega. Sigan así! | K27: Inicio | M27: Calle 95
A28: 46056 | B28: =+MONTH(A28) -> 2 | C28: =+WEEKNUM(A28) -> 6 | D28: DIEGO ALEJANDRO | E28: SANABRIA CASTRO | F28: 573132209594 | G28: 78531 | H28: Bueno | I28: Buena | J28: Muy bien | K28: Inicio | M28: 72
A29: 46056 | B29: =+MONTH(A29) -> 2 | C29: =+WEEKNUM(A29) -> 6 | D29: JOSE SANTIAGO | E29: ACOSTA BERNAL | F29: 573132747206 | G29: 78066 | H29: Regular | I29: Regular | J29: Falta puntualidad | M29: calle 95
A30: 46056 | B30: =+MONTH(A30) -> 2 | C30: =+WEEKNUM(A30) -> 6 | D30: KAREN MARGARITA | E30: DE LA HOZ CASTRO | F30: 573507993254 | G30: 78517 | H30: Bueno | I30: Buena | J30: El servicio fue excelente, muy rápido y los chicos resuelven todas las dudas, y te explican muy bien todo | K30: Inicio | M30: Taller chicó
A31: 46056 | B31: =+MONTH(A31) -> 2 | C31: =+WEEKNUM(A31) -> 6 | D31: CRISTHIAN DANIEL | E31: BENITEZ MONTAÑO | F31: 573202734329 | G31: 78171 | H31: Bueno | I31: Buena | J31: Bien servicio y buena atención | K31: Inicio | M31: Chico
A32: 46056 | B32: =+MONTH(A32) -> 2 | C32: =+WEEKNUM(A32) -> 6 | D32: JACKSON | E32: JOSE SANTANA | F32: 573151495879 | G32: 78143 | H32: Bueno | I32: Buena | K32: Inicio | M32: .
A33: 46056 | B33: =+MONTH(A33) -> 2 | C33: =+WEEKNUM(A33) -> 6 | D33: FRANKLIN | E33: FAJARDO ESTUPIÑAN | F33: 573212972134 | G33: 77544 | H33: Bueno | I33: Buena | J33: Muy agradable el servicio, por parte de la familia Minca. Los recomiendo ampliamente. 🙏🙏🙏 | K33: Inicio | M33: Javeriana
A34: 46056 | B34: =+MONTH(A34) -> 2 | C34: =+WEEKNUM(A34) -> 6 | D34: ERNESTO | E34: PATARROYO | F34: 573142063672 | G34: 78545 | H34: Bueno | I34: Buena | J34: Muy buena atención la que se recibe en cedritros taller antes llevaba la patineta en al taller de chico son demasiado groseros y no prestan buena atención, desde ahí dejé de llevarla a ese lugar | K34: Inicio | M34: Cedritos
A35: 46056 | B35: =+MONTH(A35) -> 2 | C35: =+WEEKNUM(A35) -> 6 | D35: JOHANA | E35: MUÑOZ | F35: 573102485766 | G35: 78191 | H35: Bueno | I35: Buena | J35: Deben abrir más horarios en cedritos | K35: Inicio | M35: Chico
A36: 46056 | B36: =+MONTH(A36) -> 2 | C36: =+WEEKNUM(A36) -> 6 | D36: MILENA | E36: SOTO SANGUINO | F36: 573007152300 | G36: 78003 | H36: Bueno | I36: Buena | J36: Super. Mucho mejor que en la de la javeriana, allí la atención es menos amable. | K36: Inicio | M36: Calle 72
A37: 46056 | B37: =+MONTH(A37) -> 2 | C37: =+WEEKNUM(A37) -> 6 | D37: JORGE EDUARDO | E37: CARDONA MURIEL | F37: 573193377680 | G37: 78448 | H37: Bueno | I37: Buena | J37: Siempre son amables y puntuales con las entregas. | K37: Inicio | M37: Cedritos
A38: 46056 | B38: =+MONTH(A38) -> 2 | C38: =+WEEKNUM(A38) -> 6 | D38: NICOLAS | E38: SANMIGUEL GARCIA | F38: 573012013128 | G38: 78420 | H38: Bueno | I38: Buena | J38: Rápido el servicio y buen trabajo. Muchas gracias!! | K38: Inicio | M38: Chicó
A39: 46056 | B39: =+MONTH(A39) -> 2 | C39: =+WEEKNUM(A39) -> 6 | D39: DAVID EDUARDO | E39: JAIMES GOMEZ | F39: 573193032172 | G39: 78123 | H39: Bueno | I39: Buena | J39: Excelente todo | K39: Inicio | M39: Cedritos
A40: 46056 | B40: =+MONTH(A40) -> 2 | C40: =+WEEKNUM(A40) -> 6 | D40: VANESA | E40: NUNEZ JIMENEZ | F40: 573102001809 | G40: 78169 | H40: Bueno | I40: Buena | K40: Inicio | M40: 95
...

Sheet Hoja3
A19: MES | B19: (Varios elementos) | G19: MES | H19: (Varios elementos)
A20: SEMANA | B20: 4 | G20: SEMANA | H20: 4
A22: Etiquetas de fila | B22: Cuenta de Pregunta 1 | G22: Etiquetas de fila | H22: Cuenta de Pregunta 2
A23: Bueno | B23: 41 | G23: Buena | H23: 41
A24: Malo | B24: 5 | G24: Regular | H24: 5
A25: Total general | B25: 46 | G25: Total general | H25: 46

Sheet MANYCHAT_SERVICE_SHEET
A3: =IFERROR(__xludf.DUMMYFUNCTION("QUERY('Hoja 1'!E1:E1000, ""SELECT * WHERE E=69520 OR E='69520' LIMIT 1"", 0)"),69520) -> 69520 | B3: =MATCH(A3,'Hoja 1'!G1:G892,0) -> #N/A
A6: =IFERROR(__xludf.DUMMYFUNCTION("QUERY('Hoja 1'!E1:E1000, ""SELECT * WHERE E=69520 OR E='69520' LIMIT 1"", 0)"),69520) -> 69520 | B6: =MATCH(A6,'Hoja 1'!G1:G892,0) -> #N/A
A9: =IFERROR(__xludf.DUMMYFUNCTION("QUERY('Hoja 1'!E1:E1000, ""SELECT * WHERE E=69520 OR E='69520' LIMIT 1"", 0)"),69520) -> 69520 | B9: =MATCH(A9,'Hoja 1'!G1:G892,0) -> #N/A
A12: =IFERROR(__xludf.DUMMYFUNCTION("QUERY('Hoja 1'!E1:E1000, ""SELECT * WHERE E=69520 OR E='69520' LIMIT 1"", 0)"),69520) -> 69520 | B12: =MATCH(A12,'Hoja 1'!G1:G892,0) -> #N/A
A15: =IFERROR(__xludf.DUMMYFUNCTION("QUERY('Hoja 1'!E1:E1000, ""SELECT * WHERE E=69520 OR E='69520' LIMIT 1"", 0)"),69520) -> 69520 | B15: =MATCH(A15,'Hoja 1'!G1:G892,0) -> #N/A
A18: =IFERROR(__xludf.DUMMYFUNCTION("QUERY('Hoja 1'!E1:E1000, ""SELECT * WHERE E=69651 OR E='69651' LIMIT 1"", 0)"),69651) -> 69651 | B18: =MATCH(A18,'Hoja 1'!G1:G892,0) -> #N/A
A21: =IFERROR(__xludf.DUMMYFUNCTION("QUERY('Hoja 1'!E1:E1000, ""SELECT * WHERE E=69651 OR E='69651' LIMIT 1"", 0)"),69651) -> 69651 | B21: =MATCH(A21,'Hoja 1'!G1:G892,0) -> #N/A
A24: =IFERROR(__xludf.DUMMYFUNCTION("QUERY('Hoja 1'!E1:E1000, ""SELECT * WHERE E=69688 OR E='69688' LIMIT 1"", 0)"),69688) -> 69688 | B24: =MATCH(A24,'Hoja 1'!G1:G892,0) -> #N/A
A27: =IFERROR(__xludf.DUMMYFUNCTION("QUERY('Hoja 1'!E1:E1000, ""SELECT * WHERE E=69651 OR E='69651' LIMIT 1"", 0)"),69651) -> 69651 | B27: =MATCH(A27,'Hoja 1'!G1:G892,0) -> #N/A
A30: =IFERROR(__xludf.DUMMYFUNCTION("QUERY('Hoja 1'!E1:E1000, ""SELECT * WHERE E=69688 OR E='69688' LIMIT 1"", 0)"),69688) -> 69688 | B30: =MATCH(A30,'Hoja 1'!G1:G892,0) -> #N/A
A33: =IFERROR(__xludf.DUMMYFUNCTION("QUERY('Hoja 1'!E1:E1000, ""SELECT * WHERE E=69651 OR E='69651' LIMIT 1"", 0)"),69651) -> 69651 | B33: =MATCH(A33,'Hoja 1'!G1:G892,0) -> #N/A
A36: =IFERROR(__xludf.DUMMYFUNCTION("QUERY('Hoja 1'!E1:E1000, ""SELECT * WHERE E=69651 OR E='69651' LIMIT 1"", 0)"),69651) -> 69651 | B36: =MATCH(A36,'Hoja 1'!G1:G892,0) -> #N/A
A39: =IFERROR(__xludf.DUMMYFUNCTION("QUERY('Hoja 1'!E1:E1000, ""SELECT * WHERE E=69990 OR E='69990' LIMIT 1"", 0)"),69990) -> 69990 | B39: =MATCH(A39,'Hoja 1'!G1:G892,0) -> #N/A
A42: =IFERROR(__xludf.DUMMYFUNCTION("QUERY('Hoja 1'!E1:E1000, ""SELECT * WHERE E=69990 OR E='69990' LIMIT 1"", 0)"),69990) -> 69990 | B42: =MATCH(A42,'Hoja 1'!G1:G892,0) -> #N/A
A45: =IFERROR(__xludf.DUMMYFUNCTION("QUERY('Hoja 1'!E1:E1000, ""SELECT * WHERE E=69990 OR E='69990' LIMIT 1"", 0)"),69990) -> 69990 | B45: =MATCH(A45,'Hoja 1'!G1:G892,0) -> #N/A
A48: =IFERROR(__xludf.DUMMYFUNCTION("QUERY('Hoja 1'!E1:E1000, ""SELECT * WHERE E=69933 OR E='69933' LIMIT 1"", 0)"),69933) -> 69933 | B48: =MATCH(A48,'Hoja 1'!G1:G892,0) -> #N/A
A51: =IFERROR(__xludf.DUMMYFUNCTION("QUERY('Hoja 1'!E1:E1000, ""SELECT * WHERE E=69933 OR E='69933' LIMIT 1"", 0)"),69933) -> 69933 | B51: =MATCH(A51,'Hoja 1'!G1:G892,0) -> #N/A
A54: =IFERROR(__xludf.DUMMYFUNCTION("QUERY('Hoja 1'!E1:E1000, ""SELECT * WHERE E=70281 OR E='70281' LIMIT 1"", 0)"),70281) -> 70281 | B54: =MATCH(A54,'Hoja 1'!G1:G892,0) -> #N/A
A57: =IFERROR(__xludf.DUMMYFUNCTION("QUERY('Hoja 1'!E1:E1000, ""SELECT * WHERE E=70281 OR E='70281' LIMIT 1"", 0)"),70281) -> 70281 | B57: =MATCH(A57,'Hoja 1'!G1:G892,0) -> #N/A
A60: =IFERROR(__xludf.DUMMYFUNCTION("QUERY('Hoja 1'!E1:E1000, ""SELECT * WHERE E=70261 OR E='70261' LIMIT 1"", 0)"),70261) -> 70261 | B60: =MATCH(A60,'Hoja 1'!G1:G892,0) -> #N/A
A63: =IFERROR(__xludf.DUMMYFUNCTION("QUERY('Hoja 1'!E1:E1000, ""SELECT * WHERE E=68840 OR E='68840' LIMIT 1"", 0)"),68840) -> 68840 | B63: =MATCH(A63,'Hoja 1'!G1:G892,0) -> #N/A
A66: =IFERROR(__xludf.DUMMYFUNCTION("QUERY('Hoja 1'!E1:E1000, ""SELECT * WHERE E=70261 OR E='70261' LIMIT 1"", 0)"),70261) -> 70261 | B66: =MATCH(A66,'Hoja 1'!G1:G892,0) -> #N/A
A69: =IFERROR(__xludf.DUMMYFUNCTION("QUERY('Hoja 1'!E1:E1000, ""SELECT * WHERE E=70261 OR E='70261' LIMIT 1"", 0)"),70261) -> 70261 | B69: =MATCH(A69,'Hoja 1'!G1:G892,0) -> #N/A
A72: =IFERROR(__xludf.DUMMYFUNCTION("QUERY('Hoja 1'!E1:E1000, ""SELECT * WHERE E=68840 OR E='68840' LIMIT 1"", 0)"),68840) -> 68840 | B72: =MATCH(A72,'Hoja 1'!G1:G892,0) -> #N/A
A75: =IFERROR(__xludf.DUMMYFUNCTION("QUERY('Hoja 1'!E1:E1000, ""SELECT * WHERE E=70261 OR E='70261' LIMIT 1"", 0)"),70261) -> 70261 | B75: =MATCH(A75,'Hoja 1'!G1:G892,0) -> #N/A
A78: =IFERROR(__xludf.DUMMYFUNCTION("QUERY('Hoja 1'!E1:E1000, ""SELECT * WHERE E=68840 OR E='68840' LIMIT 1"", 0)"),68840) -> 68840 | B78: =MATCH(A78,'Hoja 1'!G1:G892,0) -> #N/A
A81: =IFERROR(__xludf.DUMMYFUNCTION("QUERY('Hoja 1'!E1:E1000, ""SELECT * WHERE E=70188 OR E='70188' LIMIT 1"", 0)"),70188) -> 70188 | B81: =MATCH(A81,'Hoja 1'!G1:G892,0) -> #N/A
A84: =IFERROR(__xludf.DUMMYFUNCTION("QUERY('Hoja 1'!E1:E1000, ""SELECT * WHERE E=67274 OR E='67274' LIMIT 1"", 0)"),67274) -> 67274 | B84: =MATCH(A84,'Hoja 1'!G1:G892,0) -> #N/A
A87: =IFERROR(__xludf.DUMMYFUNCTION("QUERY('Hoja 1'!E1:E1000, ""SELECT * WHERE E=67274 OR E='67274' LIMIT 1"", 0)"),67274) -> 67274 | B87: =MATCH(A87,'Hoja 1'!G1:G892,0) -> #N/A
A90: =IFERROR(__xludf.DUMMYFUNCTION("QUERY('Hoja 1'!E1:E1000, ""SELECT * WHERE E=67274 OR E='67274' LIMIT 1"", 0)"),67274) -> 67274 | B90: =MATCH(A90,'Hoja 1'!G1:G892,0) -> #N/A
A93: =IFERROR(__xludf.DUMMYFUNCTION("QUERY('Hoja 1'!E1:E1000, ""SELECT * WHERE E=67933 OR E='67933' LIMIT 1"", 0)"),67933) -> 67933 | B93: =MATCH(A93,'Hoja 1'!G1:G892,0) -> #N/A
A96: =IFERROR(__xludf.DUMMYFUNCTION("QUERY('Hoja 1'!E1:E1000, ""SELECT * WHERE E=67933 OR E='67933' LIMIT 1"", 0)"),67933) -> 67933 | B96: =MATCH(A96,'Hoja 1'!G1:G892,0) -> #N/A
A99: =IFERROR(__xludf.DUMMYFUNCTION("QUERY('Hoja 1'!E1:E1000, ""SELECT * WHERE E=67933 OR E='67933' LIMIT 1"", 0)"),67933) -> 67933 | B99: =MATCH(A99,'Hoja 1'!G1:G892,0) -> #N/A
A102: =IFERROR(__xludf.DUMMYFUNCTION("QUERY('Hoja 1'!E1:E1000, ""SELECT * WHERE E=67933 OR E='67933' LIMIT 1"", 0)"),67933) -> 67933 | B102: =MATCH(A102,'Hoja 1'!G1:G892,0) -> #N/A
A105: =IFERROR(__xludf.DUMMYFUNCTION("QUERY('Hoja 1'!E1:E1000, ""SELECT * WHERE E=67933 OR E='67933' LIMIT 1"", 0)"),67933) -> 67933 | B105: =MATCH(A105,'Hoja 1'!G1:G892,0) -> #N/A
A108: =IFERROR(__xludf.DUMMYFUNCTION("QUERY('Hoja 1'!E1:E1000, ""SELECT * WHERE E=67251 OR E='67251' LIMIT 1"", 0)"),67251) -> 67251 | B108: =MATCH(A108,'Hoja 1'!G1:G892,0) -> #N/A
A111: =IFERROR(__xludf.DUMMYFUNCTION("QUERY('Hoja 1'!E1:E1000, ""SELECT * WHERE E=67251 OR E='67251' LIMIT 1"", 0)"),67251) -> 67251 | B111: =MATCH(A111,'Hoja 1'!G1:G892,0) -> #N/A
A114: =IFERROR(__xludf.DUMMYFUNCTION("QUERY('Hoja 1'!E1:E1000, ""SELECT * WHERE E=67251 OR E='67251' LIMIT 1"", 0)"),67251) -> 67251 | B114: =MATCH(A114,'Hoja 1'!G1:G892,0) -> #N/A
A117: =IFERROR(__xludf.DUMMYFUNCTION("QUERY('Hoja 1'!E1:E1000, ""SELECT * WHERE E=67251 OR E='67251' LIMIT 1"", 0)"),67251) -> 67251 | B117: =MATCH(A117,'Hoja 1'!G1:G892,0) -> #N/A
A120: =IFERROR(__xludf.DUMMYFUNCTION("QUERY('Hoja 1'!E1:E1000, ""SELECT * WHERE E=67251 OR E='67251' LIMIT 1"", 0)"),67251) -> 67251 | B120: =MATCH(A120,'Hoja 1'!G1:G892,0) -> #N/A
...
